<?xml version="1.0" encoding="utf-8"?>
<!-- =================================================================================== -->
<!-- |    This document was autogenerated by xacro from base.xacro                     | -->
<!-- |    EDITING THIS FILE BY HAND IS NOT RECOMMENDED                                 | -->
<!-- =================================================================================== -->
<robot name="tilthex">
  <!-- =============================================================== -->
  <!-- ==================== ROS INTERFACE MACRO ====================== -->
  <!-- =============================================================== -->
  <!-- <xacro:macro 
  		name="ros_interface_plugin_macro"
  		params="namespace">
    <gazebo>
      <plugin name="ros_interface_plugin" filename="librotors_gazebo_ros_interface_plugin.so">
        <robotNamespace>${namespace}</robotNamespace>
      </plugin>
    </gazebo>
  </xacro:macro>-->
  <!-- [kg] -->
  <!-- [kg] -->
  <link name="tilthex/base_link"/>
  <joint name="tilthex/base_joint" type="fixed">
    <origin rpy="0 0 0" xyz="0 0 0"/>
    <parent link="tilthex/base_link"/>
    <child link="tilthex/base_link_inertia"/>
  </joint>
  <link name="tilthex/base_link_inertia">
    <inertial>
      <mass value="1.8423"/>
      <!-- [kg] -->
      <origin rpy="0 0 0" xyz="0 0 0"/>
      <inertia ixx="0.001301" ixy="3.1979E-06" ixz="-3.4525E-15" iyy="0.0012994" iyz="7.8292E-15" izz="0.0025338"/>
    </inertial>
    <visual>
      <origin rpy="0 0 0" xyz="0 0 0"/>
      <geometry>
        <mesh filename="package://tilthex/meshes/base_link.STL" scale="1 1 1"/>
      </geometry>
    </visual>
    <collision>
      <origin rpy="0 0 0" xyz="0 0 0"/>
      <geometry>
        <mesh filename="package://tilthex/meshes/base_link.STL" scale="1 1 1"/>
      </geometry>
    </collision>
  </link>
  <gazebo reference="tilthex/base_link">
    <material>Gazebo/Grey</material>
  </gazebo>
  <link name="tilthex/servo1">
    <inertial>
      <!-- <origin  xyz="0.00077269 0 0.007792"  rpy="0 0 0" /> -->
      <origin rpy="0 0 0" xyz="0.00030543 -0.0145 0.00068789"/>
      <mass value="0.017333"/>
      <inertia ixx="1.4738E-06" ixy="-5.5411E-10" ixz="-2.303E-09" iyy="1.6426E-06" iyz="-1.9237E-08" izz="1.0449E-06"/>
    </inertial>
    <visual>
      <origin rpy="0 0 0" xyz="0 0 0"/>
      <geometry>
        <mesh filename="package://tilthex/meshes/servo1_Link.STL"/>
      </geometry>
    </visual>
    <collision>
      <origin rpy="0 0 0" xyz="0 0 0"/>
      <geometry>
        <mesh filename="package://tilthex/meshes/servo1_Link.STL"/>
      </geometry>
    </collision>
  </link>
  <joint name="tilthex/b_servo1" type="continuous">
    <origin rpy="-1.5708 0 0" xyz="0 -0.2857 0.014"/>
    <parent link="tilthex/base_link"/>
    <child link="tilthex/servo1"/>
    <axis xyz="1 0 0"/>
    <!-- <limit   lower="${-pi}" upper="${pi}" effort="1" velocity="10" /> -->
  </joint>
  <gazebo>
    <plugin filename="librotors_gazebo_motor_model.so" name="tilthex_servo_model_1">
      <robotNamespace>tilthex</robotNamespace>
      <jointName>tilthex/b_servo1</jointName>
      <linkName>tilthex/base_link</linkName>
      <motorType>position</motorType>
      <turningDirection>ccw</turningDirection>
      <commandSubTopic>gazebo/command/servo_position</commandSubTopic>
      <motorNumber>1</motorNumber>
      <motorPositionPubTopic>servo_position/1</motorPositionPubTopic>
      <rotorVelocitySlowdownSim>10</rotorVelocitySlowdownSim>
      <joint_control_pid>
        <p>1</p>
        <i>0.1</i>
        <d>0.01</d>
        <iMax>2</iMax>
        <iMin>-2</iMin>
        <cmdMax>1</cmdMax>
        <cmdMin>-1</cmdMin>
      </joint_control_pid>
    </plugin>
  </gazebo>
  <gazebo reference="tilthex/servo1">
    <material>Gazebo/Grey</material>
  </gazebo>
  <link name="tilthex/servo2">
    <inertial>
      <!-- <origin  xyz="0.00077269 0 0.007792"  rpy="0 0 0" /> -->
      <origin rpy="0 0 0" xyz="0.00030543 -0.0145 0.00068789"/>
      <mass value="0.017333"/>
      <inertia ixx="1.4738E-06" ixy="-5.5411E-10" ixz="-2.303E-09" iyy="1.6426E-06" iyz="-1.9237E-08" izz="1.0449E-06"/>
    </inertial>
    <visual>
      <origin rpy="0 0 0" xyz="0 0 0"/>
      <geometry>
        <mesh filename="package://tilthex/meshes/servo1_Link.STL"/>
      </geometry>
    </visual>
    <collision>
      <origin rpy="0 0 0" xyz="0 0 0"/>
      <geometry>
        <mesh filename="package://tilthex/meshes/servo1_Link.STL"/>
      </geometry>
    </collision>
  </link>
  <joint name="tilthex/b_servo2" type="continuous">
    <origin rpy="-1.5708 0 -1.0472" xyz="-0.24742 -0.14285 0.014"/>
    <parent link="tilthex/base_link"/>
    <child link="tilthex/servo2"/>
    <axis xyz="1 0 0"/>
    <!-- <limit   lower="${-pi}" upper="${pi}" effort="1" velocity="10" /> -->
  </joint>
  <gazebo>
    <plugin filename="librotors_gazebo_motor_model.so" name="tilthex_servo_model_2">
      <robotNamespace>tilthex</robotNamespace>
      <jointName>tilthex/b_servo2</jointName>
      <linkName>tilthex/base_link</linkName>
      <motorType>position</motorType>
      <turningDirection>ccw</turningDirection>
      <commandSubTopic>gazebo/command/servo_position</commandSubTopic>
      <motorNumber>2</motorNumber>
      <motorPositionPubTopic>servo_position/2</motorPositionPubTopic>
      <rotorVelocitySlowdownSim>10</rotorVelocitySlowdownSim>
      <joint_control_pid>
        <p>1</p>
        <i>0.1</i>
        <d>0.01</d>
        <iMax>2</iMax>
        <iMin>-2</iMin>
        <cmdMax>1</cmdMax>
        <cmdMin>-1</cmdMin>
      </joint_control_pid>
    </plugin>
  </gazebo>
  <gazebo reference="tilthex/servo2">
    <material>Gazebo/Grey</material>
  </gazebo>
  <link name="tilthex/servo3">
    <inertial>
      <!-- <origin  xyz="0.00077269 0 0.007792"  rpy="0 0 0" /> -->
      <origin rpy="0 0 0" xyz="0.00030543 -0.0145 0.00068789"/>
      <mass value="0.017333"/>
      <inertia ixx="1.4738E-06" ixy="-5.5411E-10" ixz="-2.303E-09" iyy="1.6426E-06" iyz="-1.9237E-08" izz="1.0449E-06"/>
    </inertial>
    <visual>
      <origin rpy="0 0 0" xyz="0 0 0"/>
      <geometry>
        <mesh filename="package://tilthex/meshes/servo1_Link.STL"/>
      </geometry>
    </visual>
    <collision>
      <origin rpy="0 0 0" xyz="0 0 0"/>
      <geometry>
        <mesh filename="package://tilthex/meshes/servo1_Link.STL"/>
      </geometry>
    </collision>
  </link>
  <joint name="tilthex/b_servo3" type="continuous">
    <origin rpy="-1.5708 0 -2.0944" xyz="-0.24742 0.14285 0.014"/>
    <parent link="tilthex/base_link"/>
    <child link="tilthex/servo3"/>
    <axis xyz="1 0 0"/>
    <!-- <limit   lower="${-pi}" upper="${pi}" effort="1" velocity="10" /> -->
  </joint>
  <gazebo>
    <plugin filename="librotors_gazebo_motor_model.so" name="tilthex_servo_model_3">
      <robotNamespace>tilthex</robotNamespace>
      <jointName>tilthex/b_servo3</jointName>
      <linkName>tilthex/base_link</linkName>
      <motorType>position</motorType>
      <turningDirection>ccw</turningDirection>
      <commandSubTopic>gazebo/command/servo_position</commandSubTopic>
      <motorNumber>3</motorNumber>
      <motorPositionPubTopic>servo_position/3</motorPositionPubTopic>
      <rotorVelocitySlowdownSim>10</rotorVelocitySlowdownSim>
      <joint_control_pid>
        <p>1</p>
        <i>0.1</i>
        <d>0.01</d>
        <iMax>2</iMax>
        <iMin>-2</iMin>
        <cmdMax>1</cmdMax>
        <cmdMin>-1</cmdMin>
      </joint_control_pid>
    </plugin>
  </gazebo>
  <gazebo reference="tilthex/servo3">
    <material>Gazebo/Grey</material>
  </gazebo>
  <link name="tilthex/servo4">
    <inertial>
      <!-- <origin  xyz="0.00077269 0 0.007792"  rpy="0 0 0" /> -->
      <origin rpy="0 0 0" xyz="0.00030543 -0.0145 0.00068789"/>
      <mass value="0.017333"/>
      <inertia ixx="1.4738E-06" ixy="-5.5411E-10" ixz="-2.303E-09" iyy="1.6426E-06" iyz="-1.9237E-08" izz="1.0449E-06"/>
    </inertial>
    <visual>
      <origin rpy="0 0 0" xyz="0 0 0"/>
      <geometry>
        <mesh filename="package://tilthex/meshes/servo1_Link.STL"/>
      </geometry>
    </visual>
    <collision>
      <origin rpy="0 0 0" xyz="0 0 0"/>
      <geometry>
        <mesh filename="package://tilthex/meshes/servo1_Link.STL"/>
      </geometry>
    </collision>
  </link>
  <joint name="tilthex/b_servo4" type="continuous">
    <origin rpy="-1.5708 0 -3.1416" xyz="0 0.2857 0.014"/>
    <parent link="tilthex/base_link"/>
    <child link="tilthex/servo4"/>
    <axis xyz="1 0 0"/>
    <!-- <limit   lower="${-pi}" upper="${pi}" effort="1" velocity="10" /> -->
  </joint>
  <gazebo>
    <plugin filename="librotors_gazebo_motor_model.so" name="tilthex_servo_model_4">
      <robotNamespace>tilthex</robotNamespace>
      <jointName>tilthex/b_servo4</jointName>
      <linkName>tilthex/base_link</linkName>
      <motorType>position</motorType>
      <turningDirection>ccw</turningDirection>
      <commandSubTopic>gazebo/command/servo_position</commandSubTopic>
      <motorNumber>4</motorNumber>
      <motorPositionPubTopic>servo_position/4</motorPositionPubTopic>
      <rotorVelocitySlowdownSim>10</rotorVelocitySlowdownSim>
      <joint_control_pid>
        <p>1</p>
        <i>0.1</i>
        <d>0.01</d>
        <iMax>2</iMax>
        <iMin>-2</iMin>
        <cmdMax>1</cmdMax>
        <cmdMin>-1</cmdMin>
      </joint_control_pid>
    </plugin>
  </gazebo>
  <gazebo reference="tilthex/servo4">
    <material>Gazebo/Grey</material>
  </gazebo>
  <link name="tilthex/servo5">
    <inertial>
      <!-- <origin  xyz="0.00077269 0 0.007792"  rpy="0 0 0" /> -->
      <origin rpy="0 0 0" xyz="0.00030543 -0.0145 0.00068789"/>
      <mass value="0.017333"/>
      <inertia ixx="1.4738E-06" ixy="-5.5411E-10" ixz="-2.303E-09" iyy="1.6426E-06" iyz="-1.9237E-08" izz="1.0449E-06"/>
    </inertial>
    <visual>
      <origin rpy="0 0 0" xyz="0 0 0"/>
      <geometry>
        <mesh filename="package://tilthex/meshes/servo1_Link.STL"/>
      </geometry>
    </visual>
    <collision>
      <origin rpy="0 0 0" xyz="0 0 0"/>
      <geometry>
        <mesh filename="package://tilthex/meshes/servo1_Link.STL"/>
      </geometry>
    </collision>
  </link>
  <joint name="tilthex/b_servo5" type="continuous">
    <origin rpy="-1.5708 0 2.0944" xyz="0.24742 0.14285 0.014"/>
    <parent link="tilthex/base_link"/>
    <child link="tilthex/servo5"/>
    <axis xyz="1 0 0"/>
    <!-- <limit   lower="${-pi}" upper="${pi}" effort="1" velocity="10" /> -->
  </joint>
  <gazebo>
    <plugin filename="librotors_gazebo_motor_model.so" name="tilthex_servo_model_5">
      <robotNamespace>tilthex</robotNamespace>
      <jointName>tilthex/b_servo5</jointName>
      <linkName>tilthex/base_link</linkName>
      <motorType>position</motorType>
      <turningDirection>ccw</turningDirection>
      <commandSubTopic>gazebo/command/servo_position</commandSubTopic>
      <motorNumber>5</motorNumber>
      <motorPositionPubTopic>servo_position/5</motorPositionPubTopic>
      <rotorVelocitySlowdownSim>10</rotorVelocitySlowdownSim>
      <joint_control_pid>
        <p>1</p>
        <i>0.1</i>
        <d>0.01</d>
        <iMax>2</iMax>
        <iMin>-2</iMin>
        <cmdMax>1</cmdMax>
        <cmdMin>-1</cmdMin>
      </joint_control_pid>
    </plugin>
  </gazebo>
  <gazebo reference="tilthex/servo5">
    <material>Gazebo/Grey</material>
  </gazebo>
  <link name="tilthex/servo6">
    <inertial>
      <!-- <origin  xyz="0.00077269 0 0.007792"  rpy="0 0 0" /> -->
      <origin rpy="0 0 0" xyz="0.00030544 -0.0145 0.00068789"/>
      <mass value="0.017333"/>
      <inertia ixx="1.4738E-06" ixy="-5.5411E-10" ixz="-2.303E-09" iyy="1.6426E-06" iyz="-1.9237E-08" izz="1.0449E-06"/>
    </inertial>
    <visual>
      <origin rpy="0 0 0" xyz="0 0 0"/>
      <geometry>
        <mesh filename="package://tilthex/meshes/servo1_Link.STL"/>
      </geometry>
    </visual>
    <collision>
      <origin rpy="0 0 0" xyz="0 0 0"/>
      <geometry>
        <mesh filename="package://tilthex/meshes/servo1_Link.STL"/>
      </geometry>
    </collision>
  </link>
  <joint name="tilthex/b_servo6" type="continuous">
    <origin rpy="-1.5708 0 1.0472" xyz="0.24742 -0.14285 0.014"/>
    <parent link="tilthex/base_link"/>
    <child link="tilthex/servo6"/>
    <axis xyz="1 0 0"/>
    <!-- <limit   lower="${-pi}" upper="${pi}" effort="1" velocity="10" /> -->
  </joint>
  <gazebo>
    <plugin filename="librotors_gazebo_motor_model.so" name="tilthex_servo_model_6">
      <robotNamespace>tilthex</robotNamespace>
      <jointName>tilthex/b_servo6</jointName>
      <linkName>tilthex/base_link</linkName>
      <motorType>position</motorType>
      <turningDirection>ccw</turningDirection>
      <commandSubTopic>gazebo/command/servo_position</commandSubTopic>
      <motorNumber>6</motorNumber>
      <motorPositionPubTopic>servo_position/6</motorPositionPubTopic>
      <rotorVelocitySlowdownSim>10</rotorVelocitySlowdownSim>
      <joint_control_pid>
        <p>1</p>
        <i>0.1</i>
        <d>0.01</d>
        <iMax>2</iMax>
        <iMin>-2</iMin>
        <cmdMax>1</cmdMax>
        <cmdMin>-1</cmdMin>
      </joint_control_pid>
    </plugin>
  </gazebo>
  <gazebo reference="tilthex/servo6">
    <material>Gazebo/Grey</material>
  </gazebo>
  <!--                       Instantiate 6 rotors                              -->
  <link name="tilthex/rotor1">
    <inertial>
      <origin rpy="0 0 0" xyz="1.4898E-07 -1.4046E-07 -0.023377"/>
      <mass value="0.019345"/>
      <inertia ixx="7.0966E-06" ixy="9.2769E-06" ixz="-3.7458E-12" iyy="1.563E-05" iyz="-1.0671E-13" izz="2.1665E-05"/>
    </inertial>
    <visual>
      <origin rpy="0 0 0" xyz="0 0 0"/>
      <geometry>
        <mesh filename="package://tilthex/meshes/rotor1_Link.STL"/>
      </geometry>
    </visual>
    <collision>
      <origin rpy="0 0 0" xyz="0 0 0"/>
      <geometry>
        <mesh filename="package://tilthex/meshes/rotor1_Link.STL"/>
      </geometry>
    </collision>
  </link>
  <joint name="tilthex/servo_r1" type="continuous">
    <origin rpy="1.5708 0 0" xyz="0 -0.0563 0"/>
    <parent link="tilthex/servo1"/>
    <child link="tilthex/rotor1"/>
    <axis xyz="0 0 1"/>
  </joint>
  <gazebo>
    <plugin filename="librotors_gazebo_motor_model.so" name="tilthex_motor_model_1">
      <robotNamespace>tilthex</robotNamespace>
      <jointName>tilthex/servo_r1</jointName>
      <linkName>tilthex/rotor1</linkName>
      <motorType>velocity</motorType>
      <turningDirection>cw</turningDirection>
      <timeConstantUp>0.0125</timeConstantUp>
      <timeConstantDown>0.025</timeConstantDown>
      <maxRotVelocity>838</maxRotVelocity>
      <motorConstant>1.7088e-05</motorConstant>
      <momentConstant>0.016</momentConstant>
      <commandSubTopic>gazebo/command/motor_speed</commandSubTopic>
      <motorNumber>1</motorNumber>
      <rotorDragCoefficient>0</rotorDragCoefficient>
      <rollingMomentCoefficient>0</rollingMomentCoefficient>
      <motorSpeedPubTopic>motor_speed/1</motorSpeedPubTopic>
      <rotorVelocitySlowdownSim>10</rotorVelocitySlowdownSim>
    </plugin>
  </gazebo>
  <gazebo reference="tilthex/rotor1">
    <material>Gazebo/Red</material>
  </gazebo>
  <link name="tilthex/rotor2">
    <inertial>
      <origin rpy="0 0 0" xyz="-1.7647E-07 -6.8929E-08 -0.023412"/>
      <mass value="0.019345"/>
      <inertia ixx="7.0966E-06" ixy="9.2769E-06" ixz="-3.7458E-12" iyy="1.563E-05" iyz="-1.0671E-13" izz="2.1665E-05"/>
    </inertial>
    <visual>
      <origin rpy="0 0 0" xyz="0 0 0"/>
      <geometry>
        <mesh filename="package://tilthex/meshes/rotor1_Link.STL"/>
      </geometry>
    </visual>
    <collision>
      <origin rpy="0 0 0" xyz="0 0 0"/>
      <geometry>
        <mesh filename="package://tilthex/meshes/rotor1_Link.STL"/>
      </geometry>
    </collision>
  </link>
  <joint name="tilthex/servo_r2" type="continuous">
    <origin rpy="1.5708 0 0" xyz="0 -0.0563 0"/>
    <parent link="tilthex/servo2"/>
    <child link="tilthex/rotor2"/>
    <axis xyz="0 0 1"/>
  </joint>
  <gazebo>
    <plugin filename="librotors_gazebo_motor_model.so" name="tilthex_motor_model_2">
      <robotNamespace>tilthex</robotNamespace>
      <jointName>tilthex/servo_r2</jointName>
      <linkName>tilthex/rotor2</linkName>
      <motorType>velocity</motorType>
      <turningDirection>ccw</turningDirection>
      <timeConstantUp>0.0125</timeConstantUp>
      <timeConstantDown>0.025</timeConstantDown>
      <maxRotVelocity>838</maxRotVelocity>
      <motorConstant>1.7088e-05</motorConstant>
      <momentConstant>0.016</momentConstant>
      <commandSubTopic>gazebo/command/motor_speed</commandSubTopic>
      <motorNumber>2</motorNumber>
      <rotorDragCoefficient>0</rotorDragCoefficient>
      <rollingMomentCoefficient>0</rollingMomentCoefficient>
      <motorSpeedPubTopic>motor_speed/2</motorSpeedPubTopic>
      <rotorVelocitySlowdownSim>10</rotorVelocitySlowdownSim>
    </plugin>
  </gazebo>
  <gazebo reference="tilthex/rotor2">
    <material>Gazebo/Blue</material>
  </gazebo>
  <link name="tilthex/rotor3">
    <inertial>
      <origin rpy="0 0 0" xyz="-3.3766E-08 3.4763E-08 -0.023377"/>
      <mass value="0.019345"/>
      <inertia ixx="7.0966E-06" ixy="9.2769E-06" ixz="-3.7458E-12" iyy="1.563E-05" iyz="-1.0671E-13" izz="2.1665E-05"/>
    </inertial>
    <visual>
      <origin rpy="0 0 0" xyz="0 0 0"/>
      <geometry>
        <mesh filename="package://tilthex/meshes/rotor1_Link.STL"/>
      </geometry>
    </visual>
    <collision>
      <origin rpy="0 0 0" xyz="0 0 0"/>
      <geometry>
        <mesh filename="package://tilthex/meshes/rotor1_Link.STL"/>
      </geometry>
    </collision>
  </link>
  <joint name="tilthex/servo_r3" type="continuous">
    <origin rpy="1.5708 0 0" xyz="0 -0.0563 0"/>
    <parent link="tilthex/servo3"/>
    <child link="tilthex/rotor3"/>
    <axis xyz="0 0 1"/>
  </joint>
  <gazebo>
    <plugin filename="librotors_gazebo_motor_model.so" name="tilthex_motor_model_3">
      <robotNamespace>tilthex</robotNamespace>
      <jointName>tilthex/servo_r3</jointName>
      <linkName>tilthex/rotor3</linkName>
      <motorType>velocity</motorType>
      <turningDirection>cw</turningDirection>
      <timeConstantUp>0.0125</timeConstantUp>
      <timeConstantDown>0.025</timeConstantDown>
      <maxRotVelocity>838</maxRotVelocity>
      <motorConstant>1.7088e-05</motorConstant>
      <momentConstant>0.016</momentConstant>
      <commandSubTopic>gazebo/command/motor_speed</commandSubTopic>
      <motorNumber>3</motorNumber>
      <rotorDragCoefficient>0</rotorDragCoefficient>
      <rollingMomentCoefficient>0</rollingMomentCoefficient>
      <motorSpeedPubTopic>motor_speed/3</motorSpeedPubTopic>
      <rotorVelocitySlowdownSim>10</rotorVelocitySlowdownSim>
    </plugin>
  </gazebo>
  <gazebo reference="tilthex/rotor3">
    <material>Gazebo/Red</material>
  </gazebo>
  <link name="tilthex/rotor4">
    <inertial>
      <origin rpy="0 0 0" xyz="1.0513E-07 -2.6158E-08 -0.023412"/>
      <mass value="0.019345"/>
      <inertia ixx="7.0966E-06" ixy="9.2769E-06" ixz="-3.7458E-12" iyy="1.563E-05" iyz="-1.0671E-13" izz="2.1665E-05"/>
    </inertial>
    <visual>
      <origin rpy="0 0 0" xyz="0 0 0"/>
      <geometry>
        <mesh filename="package://tilthex/meshes/rotor1_Link.STL"/>
      </geometry>
    </visual>
    <collision>
      <origin rpy="0 0 0" xyz="0 0 0"/>
      <geometry>
        <mesh filename="package://tilthex/meshes/rotor1_Link.STL"/>
      </geometry>
    </collision>
  </link>
  <joint name="tilthex/servo_r4" type="continuous">
    <origin rpy="1.5708 0 0" xyz="0 -0.0563 0"/>
    <parent link="tilthex/servo4"/>
    <child link="tilthex/rotor4"/>
    <axis xyz="0 0 1"/>
  </joint>
  <gazebo>
    <plugin filename="librotors_gazebo_motor_model.so" name="tilthex_motor_model_4">
      <robotNamespace>tilthex</robotNamespace>
      <jointName>tilthex/servo_r4</jointName>
      <linkName>tilthex/rotor4</linkName>
      <motorType>velocity</motorType>
      <turningDirection>ccw</turningDirection>
      <timeConstantUp>0.0125</timeConstantUp>
      <timeConstantDown>0.025</timeConstantDown>
      <maxRotVelocity>838</maxRotVelocity>
      <motorConstant>1.7088e-05</motorConstant>
      <momentConstant>0.016</momentConstant>
      <commandSubTopic>gazebo/command/motor_speed</commandSubTopic>
      <motorNumber>4</motorNumber>
      <rotorDragCoefficient>0</rotorDragCoefficient>
      <rollingMomentCoefficient>0</rollingMomentCoefficient>
      <motorSpeedPubTopic>motor_speed/4</motorSpeedPubTopic>
      <rotorVelocitySlowdownSim>10</rotorVelocitySlowdownSim>
    </plugin>
  </gazebo>
  <gazebo reference="tilthex/rotor4">
    <material>Gazebo/Blue</material>
  </gazebo>
  <link name="tilthex/rotor5">
    <inertial>
      <origin rpy="0 0 0" xyz="-1.948E-07 -4.041E-08 -0.023377"/>
      <mass value="0.019345"/>
      <inertia ixx="7.0966E-06" ixy="9.2769E-06" ixz="-3.7458E-12" iyy="1.563E-05" iyz="-1.0671E-13" izz="2.1665E-05"/>
    </inertial>
    <visual>
      <origin rpy="0 0 0" xyz="0 0 0"/>
      <geometry>
        <mesh filename="package://tilthex/meshes/rotor1_Link.STL"/>
      </geometry>
    </visual>
    <collision>
      <origin rpy="0 0 0" xyz="0 0 0"/>
      <geometry>
        <mesh filename="package://tilthex/meshes/rotor1_Link.STL"/>
      </geometry>
    </collision>
  </link>
  <joint name="tilthex/servo_r5" type="continuous">
    <origin rpy="1.5708 0 0" xyz="0 -0.0563 0"/>
    <parent link="tilthex/servo5"/>
    <child link="tilthex/rotor5"/>
    <axis xyz="0 0 1"/>
  </joint>
  <gazebo>
    <plugin filename="librotors_gazebo_motor_model.so" name="tilthex_motor_model_5">
      <robotNamespace>tilthex</robotNamespace>
      <jointName>tilthex/servo_r5</jointName>
      <linkName>tilthex/rotor5</linkName>
      <motorType>velocity</motorType>
      <turningDirection>cw</turningDirection>
      <timeConstantUp>0.0125</timeConstantUp>
      <timeConstantDown>0.025</timeConstantDown>
      <maxRotVelocity>838</maxRotVelocity>
      <motorConstant>1.7088e-05</motorConstant>
      <momentConstant>0.016</momentConstant>
      <commandSubTopic>gazebo/command/motor_speed</commandSubTopic>
      <motorNumber>5</motorNumber>
      <rotorDragCoefficient>0</rotorDragCoefficient>
      <rollingMomentCoefficient>0</rollingMomentCoefficient>
      <motorSpeedPubTopic>motor_speed/5</motorSpeedPubTopic>
      <rotorVelocitySlowdownSim>10</rotorVelocitySlowdownSim>
    </plugin>
  </gazebo>
  <gazebo reference="tilthex/rotor5">
    <material>Gazebo/Red</material>
  </gazebo>
  <link name="tilthex/rotor6">
    <inertial>
      <origin rpy="0 0 0" xyz="-1.4657E-07 -5.6663E-09 -0.023412"/>
      <mass value="0.019345"/>
      <inertia ixx="7.0966E-06" ixy="9.2769E-06" ixz="-3.7458E-12" iyy="1.563E-05" iyz="-1.0671E-13" izz="2.1665E-05"/>
    </inertial>
    <visual>
      <origin rpy="0 0 0" xyz="0 0 0"/>
      <geometry>
        <mesh filename="package://tilthex/meshes/rotor1_Link.STL"/>
      </geometry>
    </visual>
    <collision>
      <origin rpy="0 0 0" xyz="0 0 0"/>
      <geometry>
        <mesh filename="package://tilthex/meshes/rotor1_Link.STL"/>
      </geometry>
    </collision>
  </link>
  <joint name="tilthex/servo_r6" type="continuous">
    <origin rpy="1.5708 0 0" xyz="0 -0.0563 0"/>
    <parent link="tilthex/servo6"/>
    <child link="tilthex/rotor6"/>
    <axis xyz="0 0 1"/>
  </joint>
  <gazebo>
    <plugin filename="librotors_gazebo_motor_model.so" name="tilthex_motor_model_6">
      <robotNamespace>tilthex</robotNamespace>
      <jointName>tilthex/servo_r6</jointName>
      <linkName>tilthex/rotor6</linkName>
      <motorType>velocity</motorType>
      <turningDirection>ccw</turningDirection>
      <timeConstantUp>0.0125</timeConstantUp>
      <timeConstantDown>0.025</timeConstantDown>
      <maxRotVelocity>838</maxRotVelocity>
      <motorConstant>1.7088e-05</motorConstant>
      <momentConstant>0.016</momentConstant>
      <commandSubTopic>gazebo/command/motor_speed</commandSubTopic>
      <motorNumber>6</motorNumber>
      <rotorDragCoefficient>0</rotorDragCoefficient>
      <rollingMomentCoefficient>0</rollingMomentCoefficient>
      <motorSpeedPubTopic>motor_speed/6</motorSpeedPubTopic>
      <rotorVelocitySlowdownSim>10</rotorVelocitySlowdownSim>
    </plugin>
  </gazebo>
  <gazebo reference="tilthex/rotor6">
    <material>Gazebo/Blue</material>
  </gazebo>
  <!-- IMU link -->
  <link name="tilthex/imu_link">
    <inertial>
      <inertia ixx="0.00001" ixy="0.0" ixz="0.0" iyy="0.00001" iyz="0.0" izz="0.00001"/>
      <mass value="0.015"/>
      <!-- [kg] -->
      <origin rpy="0 0 0" xyz="0 0 0"/>
    </inertial>
  </link>
  <!-- IMU joint -->
  <joint name="tilthex/imu_joint" type="revolute">
    <origin rpy="0 0 0" xyz="0 0 0"/>
    <parent link="tilthex/base_link"/>
    <child link="tilthex/imu_link"/>
    <limit effort="0" lower="0" upper="0" velocity="0"/>
  </joint>
  <gazebo>
    <plugin filename="librotors_gazebo_imu_plugin.so" name="rotors_gazebo_imu_plugin">
      <!-- A good description of the IMU parameters can be found in the kalibr documentation:
           https://github.com/ethz-asl/kalibr/wiki/IMU-Noise-Model-and-Intrinsics -->
      <robotNamespace>tilthex</robotNamespace>
      <!-- (string, required): ros namespace in which the messages are published -->
      <linkName>tilthex/imu_link</linkName>
      <!-- (string, required): name of the body which holds the IMU sensor -->
      <imuTopic>imu</imuTopic>
      <!-- (string): name of the sensor output topic and prefix of service names (defaults to imu) -->
      <gyroscopeNoiseDensity>0.0003394</gyroscopeNoiseDensity>
      <!-- Gyroscope noise density (two-sided spectrum) [rad/s/sqrt(Hz)] -->
      <gyroscopeRandomWalk>3.8785e-05</gyroscopeRandomWalk>
      <!-- Gyroscope bias random walk [rad/s/s/sqrt(Hz)] -->
      <gyroscopeBiasCorrelationTime>1000.0</gyroscopeBiasCorrelationTime>
      <!-- Gyroscope bias correlation time constant [s] -->
      <gyroscopeTurnOnBiasSigma>0.0087</gyroscopeTurnOnBiasSigma>
      <!-- Gyroscope turn on bias standard deviation [rad/s] -->
      <accelerometerNoiseDensity>0.004</accelerometerNoiseDensity>
      <!-- Accelerometer noise density (two-sided spectrum) [m/s^2/sqrt(Hz)] -->
      <accelerometerRandomWalk>0.006</accelerometerRandomWalk>
      <!-- Accelerometer bias random walk. [m/s^2/s/sqrt(Hz)] -->
      <accelerometerBiasCorrelationTime>300.0</accelerometerBiasCorrelationTime>
      <!-- Accelerometer bias correlation time constant [s] -->
      <accelerometerTurnOnBiasSigma>0.196</accelerometerTurnOnBiasSigma>
      <!-- Accelerometer turn on bias standard deviation [m/s^2] -->
    </plugin>
  </gazebo>
  <!--
  <xacro:if value="$(arg enable_ground_truth)">
    <xacro:ground_truth_imu_and_odometry namespace="${namespace}" parent_link="${namespace}/base_link" />
  </xacro:if>-->
</robot>

